test_execution_failure.byte: failure: This error was triggered on purpose.
